Traceback (most recent call last):
  File "<pyshell#20>", line 2, in <module>
Exception: これはエラーメッセージです。
